('110.86.176.136', '46109')
Traceback (most recent call last):
  File "/usr/local/anaconda3/lib/python3.7/site-packages/pymongo/pool.py", line 1038, in _get_socket_no_auth
    sock_info = self.sockets.pop()
KeyError: 'pop from an empty set'

During handling of the above exception, another exception occurred:

Traceback (most recent call last):
  File "/usr/local/anaconda3/lib/python3.7/site-packages/pymongo/pool.py", line 968, in connect
    sock = _configured_socket(self.address, self.opts)
  File "/usr/local/anaconda3/lib/python3.7/site-packages/pymongo/pool.py", line 843, in _configured_socket
    sock = _create_connection(address, options)
  File "/usr/local/anaconda3/lib/python3.7/site-packages/pymongo/pool.py", line 824, in _create_connection
    raise err
  File "/usr/local/anaconda3/lib/python3.7/site-packages/pymongo/pool.py", line 817, in _create_connection
    sock.connect(sa)
socket.timeout: timed out

During handling of the above exception, another exception occurred:

Traceback (most recent call last):
  File "proxy.py", line 92, in verify_proxydb
    for dbitem in dblist:
  File "/usr/local/anaconda3/lib/python3.7/site-packages/pymongo/cursor.py", line 1189, in next
    if len(self.__data) or self._refresh():
  File "/usr/local/anaconda3/lib/python3.7/site-packages/pymongo/cursor.py", line 1104, in _refresh
    self.__send_message(q)
  File "/usr/local/anaconda3/lib/python3.7/site-packages/pymongo/cursor.py", line 931, in __send_message
    operation, exhaust=self.__exhaust, address=self.__address)
  File "/usr/local/anaconda3/lib/python3.7/site-packages/pymongo/mongo_client.py", line 1145, in _send_message_with_response
    exhaust)
  File "/usr/local/anaconda3/lib/python3.7/site-packages/pymongo/mongo_client.py", line 1156, in _reset_on_error
    return func(*args, **kwargs)
  File "/usr/local/anaconda3/lib/python3.7/site-packages/pymongo/server.py", line 85, in send_message_with_response
    with self.get_socket(all_credentials, exhaust) as sock_info:
  File "/usr/local/anaconda3/lib/python3.7/contextlib.py", line 112, in __enter__
    return next(self.gen)
  File "/usr/local/anaconda3/lib/python3.7/site-packages/pymongo/pool.py", line 1004, in get_socket
    sock_info = self._get_socket_no_auth()
  File "/usr/local/anaconda3/lib/python3.7/site-packages/pymongo/pool.py", line 1041, in _get_socket_no_auth
    sock_info = self.connect()
  File "/usr/local/anaconda3/lib/python3.7/site-packages/pymongo/pool.py", line 972, in connect
    _raise_connection_failure(self.address, error)
  File "/usr/local/anaconda3/lib/python3.7/site-packages/pymongo/pool.py", line 273, in _raise_connection_failure
    raise NetworkTimeout(msg)
pymongo.errors.NetworkTimeout: dds-2zeabb0862781c64-pub.mongodb.rds.aliyuncs.com:3717: timed out

